Workbook

Sheet Expert Panel Profile
A1: Panel ID | B1: Background | C1: Domain | D1: Role
A2: Expert A | B2: Educational Technology Specialist (Professor in EdTech / Digital Learning) | C2: Technology-Enabled Learning (TEL), Online Student Engagement (OSE) | D2: Validates digital LMS platform accessibility, mobile learning utility, and active online participation measures adapted from Kampa (2023) and Dixson (2015) in an ODL context.
A3: Expert B | B3: ODL & Higher Education Policy Expert (Specialist in Distance Education & NEP 2020) | C3: Flexible Learning (FL), Interdisciplinary Learning (IDL) | D3: Evaluates schedule/assessment flexibility and multi-disciplinary credit transfer items to ensure alignment with NEP 2020 ODL guidelines and adapted scales (El Galad et al., 2024; Lattuca et al., 2012).
A4: Expert C | B4: Educational Psychologist (Adult Learning & Self-Regulation Researcher) | C4: Learner Autonomy (LA), Age (AGE) | D4: Assesses self-directed learning, self-monitoring, and motivation items (Afacan Adanır & Güven, 2023). Verifies whether the Age moderator appropriately captures non-traditional/working adult demographics.
A5: Expert D | B5: Experiential Pedagogy Specialist (Faculty specializing in Applied/Vocational Learning) | C5: Experiential Learning (EL) | D5: Checks if practical skill application, real-world problem solving, and reflective learning items (Walker & Rocconi, 2021) are realistically measured within a distance education model.
A6: Expert E | B6: Graduate Employability Scholar (University Placement Director / Employability Researcher) | C6: Self-Perceived Graduate Employability (SPE) | D6: Validates self-perceived skills, employment market confidence, and job readiness items adapted from Rothwell et al. (2008) for open university graduates.
A7: Expert F | B7: Industry Talent Acquisition Executive (Senior HR Director / Corporate Recruiter) | C7: Experiential Learning (EL), Self-Perceived Graduate Employability (SPE) | D7: Provides external industry validity to confirm whether the competencies in SPE and practical skills in EL align with employer expectations and labor market needs.
A8: Expert G | B8: Quantitative Psychometrician | C8: All Constructs | D8: Evaluates reflective measurement structures, double-barreled item detection, 5-point Likert scale clarity, and overall psychometric integrity of all 35 survey items.

Sheet Expert Ratings
A1: Domain | B1: Code | C1: Statement | D1: Expert A | E1: Expert B | F1: Expert C | G1: Expert D | H1: Expert E | I1: Expert F | J1: Expert G | K1: Score | L1: Revised To
A2: Technology-Enabled Learning (TEL) | B2: TEL1 | C2: My ODL programme provides adequate digital learning resources. | D2: 1 | E2: 3 | F2: 3 | G2: 3 | H2: 3 | I2: 4 | J2: 3 | K2: =SUM(D2:J2) -> 20
B3: TEL2 | C3: I can easily access my institution's online learning platform. | D3: 3 | E3: 4 | F3: 3 | G3: 2 | H3: 4 | I3: 3 | J3: 4 | K3: =SUM(D3:J3) -> 23
B4: TEL3 | C4: Digital course materials are readily accessible to me. | D4: 4 | E4: 3 | F4: 3 | G4: 4 | H4: 3 | I4: 3 | J4: 2 | K4: =SUM(D4:J4) -> 22
B5: TEL4 | C5: Mobile and digital technologies are useful for my learning. | D5: 1 | E5: 3 | F5: 3 | G5: 3 | H5: 3 | I5: 4 | J5: 3 | K5: =SUM(D5:J5) -> 20
B6: TEL5 | C6: Technology-enabled facilities support my learning effectively. | D6: 3 | E6: 3 | F6: 3 | G6: 2 | H6: 3 | I6: 3 | J6: 3 | K6: =SUM(D6:J6) -> 20
A7: Flexible Learning (FL) | B7: FL1 | C7: I can manage my study schedule according to my personal circumstances. | D7: 3 | E7: 3 | F7: 3 | G7: 2 | H7: 3 | I7: 3 | J7: 4 | K7: =SUM(D7:J7) -> 21
B8: FL2 | C8: I have flexibility in when I access learning materials. | D8: 4 | E8: 3 | F8: 3 | G8: 3 | H8: 3 | I8: 4 | J8: 3 | K8: =SUM(D8:J8) -> 23
B9: FL3 | C9: I have flexibility regarding where I undertake my studies. | D9: 3 | E9: 4 | F9: 3 | G9: 3 | H9: 3 | I9: 3 | J9: 3 | K9: =SUM(D9:J9) -> 22
B10: FL4 | C10: My programme accommodates learners with different personal commitments. | D10: 2 | E10: 3 | F10: 3 | G10: 3 | H10: 4 | I10: 3 | J10: 3 | K10: =SUM(D10:J10) -> 21
B11: FL5 | C11: My programme provides flexibility in assessment arrangements. | D11: 4 | E11: 3 | F11: 4 | G11: 3 | H11: 3 | I11: 3 | J11: 3 | K11: =SUM(D11:J11) -> 23
A12: Interdisciplinary Learning (IDL) | B12: IDL1 | C12: My programme exposes me to knowledge from different disciplines. | D12: 3 | E12: 3 | F12: 3 | G12: 3 | H12: 4 | I12: 3 | J12: 3 | K12: =SUM(D12:J12) -> 22
B13: IDL2 | C13: I can connect ideas from different academic fields. | D13: 3 | E13: 3 | F13: 4 | G13: 3 | H13: 3 | I13: 3 | J13: 3 | K13: =SUM(D13:J13) -> 22
B14: IDL3 | C14: I can apply perspectives from different disciplines when solving problems. | D14: 4 | E14: 3 | F14: 3 | G14: 3 | H14: 3 | I14: 3 | J14: 3 | K14: =SUM(D14:J14) -> 22
B15: IDL4 | C15: Interdisciplinary learning helps me understand complex issues. | D15: 3 | E15: 3 | F15: 3 | G15: 4 | H15: 3 | I15: 3 | J15: 3 | K15: =SUM(D15:J15) -> 22
B16: IDL5 | C16: My studies enable me to integrate knowledge across subject areas. | D16: 3 | E16: 3 | F16: 3 | G16: 3 | H16: 4 | I16: 3 | J16: 3 | K16: =SUM(D16:J16) -> 22
A17: Online Teaching Self-Efficacy (OTSE) | B17: OTSE1 | C17: I am confident in engaging students effectively in an online teaching environment. | D17: 3 | E17: 3 | F17: 3 | G17: 3 | H17: 3 | I17: 4 | J17: 3 | K17: =SUM(D17:J17) -> 22
B18: OTSE2 | C18: I am confident in selecting appropriate instructional strategies for online teaching. | D18: 3 | E18: 1 | F18: 3 | G18: 3 | H18: 3 | I18: 3 | J18: 4 | K18: =SUM(D18:J18) -> 20
B19: OTSE3 | C19: I am confident in managing student participation in online learning environments. | D19: 3 | E19: 3 | F19: 3 | G19: 3 | H19: 3 | I19: 3 | J19: 3 | K19: =SUM(D19:J19) -> 21
B20: OTSE4 | C20: I am confident in using digital technologies to facilitate online learning. | D20: 3 | E20: 2 | F20: 3 | G20: 3 | H20: 3 | I20: 3 | J20: 3 | K20: =SUM(D20:J20) -> 20
B21: OTSE5 | C21: I am confident in assessing and providing feedback to students through online platforms. | D21: 4 | E21: 3 | F21: 3 | G21: 3 | H21: 3 | I21: 3 | J21: 4 | K21: =SUM(D21:J21) -> 23
A22: Experiential Learning (EL) | B22: EL1 | C22: My programme provides opportunities to apply theoretical knowledge practically. | D22: 4 | E22: 3 | F22: 3 | G22: 3 | H22: 3 | I22: 3 | J22: 3 | K22: =SUM(D22:J22) -> 22
B23: EL2 | C23: I participate in learning activities related to real-world situations. | D23: 3 | E23: 4 | F23: 3 | G23: 3 | H23: 2 | I23: 3 | J23: 3 | K23: =SUM(D23:J23) -> 21
B24: EL3 | C24: My learning activities develop practical or professional skills. | D24: 3 | E24: 3 | F24: 3 | G24: 3 | H24: 3 | I24: 2 | J24: 3 | K24: =SUM(D24:J24) -> 20
B25: EL4 | C25: What I learnt, I applied. | D25: 2 | E25: 3 | F25: 3 | G25: 4 | H25: 2 | I25: 4 | J25: 3 | K25: =SUM(D25:J25) -> 21 | L25: I reflect on what I learn and how it can be applied.
B26: EL5 | C26: My studies involve solving practical or real-world problems. | D26: 3 | E26: 3 | F26: 3 | G26: 3 | H26: 3 | I26: 3 | J26: 3 | K26: =SUM(D26:J26) -> 21
A27: Learner Autonomy (LA) | B27: LA1 | C27: I take responsibility for planning my learning activities. | D27: 3 | E27: 3 | F27: 3 | G27: 3 | H27: 3 | I27: 3 | J27: 3 | K27: =SUM(D27:J27) -> 21
B28: LA2 | C28: I can manage my studies without continuous supervision. | D28: 3 | E28: 3 | F28: 3 | G28: 3 | H28: 3 | I28: 4 | J28: 3 | K28: =SUM(D28:J28) -> 22
B29: LA3 | C29: I monitor my own academic progress. | D29: 3 | E29: 3 | F29: 3 | G29: 3 | H29: 3 | I29: 3 | J29: 2 | K29: =SUM(D29:J29) -> 20
B30: LA4 | C30: I reflect on my strengths and weaknesses as a learner. | D30: 4 | E30: 3 | F30: 1 | G30: 3 | H30: 3 | I30: 3 | J30: 3 | K30: =SUM(D30:J30) -> 20
B31: LA5 | C31: I remain motivated to continue learning independently. | D31: 3 | E31: 2 | F31: 4 | G31: 3 | H31: 3 | I31: 3 | J31: 4 | K31: =SUM(D31:J31) -> 22
A32: Online Student Engagement (OSE) | B32: OSE1 | C32: I actively participate in online learning activities. | D32: 2 | E32: 3 | F32: 3 | G32: 3 | H32: 3 | I32: 4 | J32: 3 | K32: =SUM(D32:J32) -> 21
B33: OSE2 | C33: I regularly engage with online course materials. | D33: 3 | E33: 3 | F33: 3 | G33: 4 | H33: 3 | I33: 3 | J33: 3 | K33: =SUM(D33:J33) -> 22
B34: OSE3 | C34: I actively communicate with instructors through online platforms. | D34: 3 | E34: 3 | F34: 3 | G34: 3 | H34: 3 | I34: 3 | J34: 3 | K34: =SUM(D34:J34) -> 21
B35: OSE4 | C35: I participate in online discussions and collaborative activities. | D35: 3 | E35: 4 | F35: 3 | G35: 3 | H35: 2 | I35: 4 | J35: 3 | K35: =SUM(D35:J35) -> 22
B36: OSE5 | C36: I consistently complete my online learning tasks. | D36: 3 | E36: 4 | F36: 3 | G36: 3 | H36: 3 | I36: 3 | J36: 3 | K36: =SUM(D36:J36) -> 22
A37: Self-Perceived Graduate Employability (SPE) | B37: SPE1 | C37: My education has prepared me for employment. | D37: 3 | E37: 4 | F37: 2 | G37: 3 | H37: 3 | I37: 3 | J37: 3 | K37: =SUM(D37:J37) -> 21
B38: SPE2 | C38: I possess competencies valued by employers. | D38: 3 | E38: 3 | F38: 4 | G38: 3 | H38: 3 | I38: 4 | J38: 3 | K38: =SUM(D38:J38) -> 23
B39: SPE3 | C39: I am confident about obtaining suitable employment after completing my programme. | D39: 4 | E39: 3 | F39: 4 | G39: 3 | H39: 3 | I39: 3 | J39: 3 | K39: =SUM(D39:J39) -> 23
B40: SPE4 | C40: I understand employment opportunities related to my field of study. | D40: 4 | E40: 3 | F40: 3 | G40: 3 | H40: 4 | I40: 3 | J40: 3 | K40: =SUM(D40:J40) -> 23
...

Sheet Relevance
A1: ID | B1: Relevant
A2: ='Expert Ratings'!B2 -> TEL1 | B2: =COUNTIF('Expert Ratings'!D2:J2,">=3")/COUNT('Expert Ratings'!D2:J2) -> 0.85714286
A3: ='Expert Ratings'!B3 -> TEL2 | B3: =COUNTIF('Expert Ratings'!D3:J3,">=3")/COUNT('Expert Ratings'!D3:J3) -> 0.85714286
A4: ='Expert Ratings'!B4 -> TEL3 | B4: =COUNTIF('Expert Ratings'!D4:J4,">=3")/COUNT('Expert Ratings'!D4:J4) -> 0.85714286
A5: ='Expert Ratings'!B5 -> TEL4 | B5: =COUNTIF('Expert Ratings'!D5:J5,">=3")/COUNT('Expert Ratings'!D5:J5) -> 0.85714286
A6: ='Expert Ratings'!B6 -> TEL5 | B6: =COUNTIF('Expert Ratings'!D6:J6,">=3")/COUNT('Expert Ratings'!D6:J6) -> 0.85714286
A7: ='Expert Ratings'!B7 -> FL1 | B7: =COUNTIF('Expert Ratings'!D7:J7,">=3")/COUNT('Expert Ratings'!D7:J7) -> 0.85714286
A8: ='Expert Ratings'!B8 -> FL2 | B8: =COUNTIF('Expert Ratings'!D8:J8,">=3")/COUNT('Expert Ratings'!D8:J8) -> 1
A9: ='Expert Ratings'!B9 -> FL3 | B9: =COUNTIF('Expert Ratings'!D9:J9,">=3")/COUNT('Expert Ratings'!D9:J9) -> 1
A10: ='Expert Ratings'!B10 -> FL4 | B10: =COUNTIF('Expert Ratings'!D10:J10,">=3")/COUNT('Expert Ratings'!D10:J10) -> 0.85714286
A11: ='Expert Ratings'!B11 -> FL5 | B11: =COUNTIF('Expert Ratings'!D11:J11,">=3")/COUNT('Expert Ratings'!D11:J11) -> 1
A12: ='Expert Ratings'!B12 -> IDL1 | B12: =COUNTIF('Expert Ratings'!D12:J12,">=3")/COUNT('Expert Ratings'!D12:J12) -> 1
A13: ='Expert Ratings'!B13 -> IDL2 | B13: =COUNTIF('Expert Ratings'!D13:J13,">=3")/COUNT('Expert Ratings'!D13:J13) -> 1
... A41: ='Expert Ratings'!B41 -> SPE5 | B41: =COUNTIF('Expert Ratings'!D41:J41,">=3")/COUNT('Expert Ratings'!D41:J41) -> 0.85714286
